<?xml version="1.0" encoding="utf-8"?>
<mujoco model="xmlrobot">
	<compiler/>
	<option gravity="0 0 0"/>
	<size nconmax="500" njmax="1000"/>
	<custom/>
	<default>
		<joint armature="1" damping="1" limited="true"/>
		<geom conaffinity="0" condim="3" margin="0.01" rgba="0.8 0.6 0.4 1"/>
	</default>
	<asset>
		<texture builtin="gradient" height="100" rgb1="1 1 1" rgb2="0 0 0" type="skybox" width="100"/>
		<texture builtin="flat" height="1278" mark="cross" markrgb="1 1 1" name="texgeom" random="0.01" rgb1="0.8 0.6 0.4" rgb2="0.8 0.6 0.4" type="cube" width="127"/>
		<texture builtin="checker" height="100" name="texplane" rgb1="0 0 0" rgb2="0.8 0.8 0.8" type="2d" width="100"/>
		<material name="MatPlane" reflectance="0.5" shininess="1" specular="1" texrepeat="60 60" texture="texplane"/>
		<material name="geom" texture="texgeom" texuniform="true"/>
	</asset>
	<worldbody>
		<light cutoff="100" diffuse="1 1 1" dir="0 0 -1.3" directional="true" exponent="1" pos="0 0 1.3" specular="0.1 0.1 0.1"/>
		<geom conaffinity="1" condim="3" material="MatPlane" name="floor" pos="0 0 0" rgba="0.8 0.9 0.8 1" size="40 40 40" type="plane"/>
		<body name="root" pos="0 0 2" euler="0 0 0">
			<geom name="geomroot" pos="0 0 2" size="0.0005" type="sphere" euler="0 0 0"/>
			<body name="body8" pos="0 0 0" euler="0 0 0">
				<geom name="geombody8" pos="-0.02 0 0" size="0.2 0.4 0.05" type="box" euler="0 0 0"/>
				<joint axis="1 0 0" name="joint_joint80" pos="0 0 0" range="-45 45" type="hinge"/>
			</body>
			<body name="body7" pos="0 0 0" euler="0 0 0">
				<geom name="geombody7" pos="-0.02 0 0" size="0.2 0.4 0.05" type="box" euler="0 0 0"/>
				<joint axis="1 0 0" name="joint_joint79" pos="0 0 0" range="-45 45" type="hinge"/>
			</body>
			<body name="body6" pos="0 0 0" euler="0 0 0">
				<geom name="geombody6" pos="-0.02 0 0" size="0.2 0.4 0.05" type="box" euler="0 0 0"/>
				<joint axis="1 0 0" name="joint_joint65" pos="0 0 0" range="-45 45" type="hinge"/>
			</body>
			<body name="body5" pos="0 0 0" euler="0 0 0">
				<geom name="geombody5" pos="-0.02 0 0" size="0.2 0.4 0.05" type="box" euler="0 0 0"/>
				<joint axis="1 0 0" name="joint_joint57" pos="0 0 0" range="-45 45" type="hinge"/>
				<body name="limbmount11" pos="-0.225 -0.2 0" euler="0 90 0">
					<geom fromto="0 0 0 0.025 0 0" name="geomlimbmount11" size="0.025" type="capsule" euler="0 0 0"/>
					<joint axis="1 0 0" name="joint_joint81" pos="0 0 0" range="-45 45" type="hinge"/>
				</body>
			</body>
			<body name="body4" pos="0 0 0" euler="0 0 0">
				<geom name="geombody4" pos="-0.02 0 0" size="0.2 0.4 0.05" type="box" euler="0 0 0"/>
				<joint axis="1 0 0" name="joint_joint31" pos="0 0 0" range="-45 45" type="hinge"/>
			</body>
			<body name="body3" pos="0 0 0" euler="0 0 0">
				<geom name="geombody3" pos="-0.02 0 0" size="0.2 0.4 0.05" type="box" euler="0 0 0"/>
				<joint axis="1 0 0" name="joint_joint8" pos="0 0 0" range="-45 45" type="hinge"/>
				<body name="limbmount9" pos="0.1875 -0.2 0" euler="0 90 0">
					<geom fromto="0 0 0 0.025 0 0" name="geomlimbmount9" size="0.025" type="capsule" euler="0 0 0"/>
					<joint axis="1 0 0" name="joint_joint24" pos="0 0 0" range="-45 45" type="hinge"/>
					<body name="motor14" pos="0 0 0" euler="0 -90 0">
						<geom fromto="0 0 0 0.042 0 0" name="geommotor14" pos="0 0 0" size="0.066" type="cylinder" euler="0 0 0"/>
						<joint axis="1 0 0" name="joint_joint46" pos="0 0 0" range="-45 45" type="hinge"/>
						<body name="limblink20" pos="0 0 0" euler="0 90 0">
							<geom fromto="0 0 0 0.3 0 0" name="geomlimblink20" size="0.06" type="capsule" euler="0 0 0"/>
							<joint axis="0 1 0" name="joint_joint66" pos="0 0 0" range="-0.1 0.1" type="hinge"/>
							<body name="leg17" pos="0.6 0 0" euler="0 0 0">
								<geom fromto="0 0 0 0.8 0 0" name="geomleg17" size="0.08" type="capsule" euler="0 0 0"/>
								<joint axis="1 0 0" damping="2.5" name="joint_joint70" pos="0 0 0" range="-0.1 0.1" stiffness="80" type="slide"/>
							</body>
						</body>
						<body name="limblink10" pos="0 0 0" euler="0 90 0">
							<geom fromto="0 0 0 0.3 0 0" name="geomlimblink10" size="0.06" type="capsule" euler="0 0 0"/>
							<joint axis="0 1 0" name="joint_joint47" pos="0 0 0" range="-0.1 0.1" type="hinge"/>
						</body>
					</body>
					<body name="motor8" pos="0 0 0" euler="0 -90 0">
						<geom fromto="0 0 0 0.042 0 0" name="geommotor8" pos="0 0 0" size="0.066" type="cylinder" euler="0 0 0"/>
						<joint axis="1 0 0" name="joint_joint32" pos="0 0 0" range="-45 45" type="hinge"/>
						<body name="limblink21" pos="0.015 0 0" euler="0 90 0">
							<geom fromto="0 0 0 0.15 0 0" name="geomlimblink21" size="0.03" type="capsule" euler="0 0 0"/>
							<joint axis="0 1 0" name="joint_joint68" pos="0 0 0" range="-0.1 0.1" type="hinge"/>
							<body name="leg16" pos="0.6 0 0" euler="0 0 0">
								<geom fromto="0 0 0 0.8 0 0" name="geomleg16" size="0.08" type="capsule" euler="0 0 0"/>
								<joint axis="1 0 0" damping="2.5" name="joint_joint69" pos="0 0 0" range="-0.1 0.1" stiffness="80" type="slide"/>
							</body>
						</body>
						<body name="limblink18" pos="0.015 0 0" euler="0 90 0">
							<geom fromto="0 0 0 0.15 0 0" name="geomlimblink18" size="0.03" type="capsule" euler="0 0 0"/>
							<joint axis="0 1 0" name="joint_joint61" pos="0 0 0" range="-0.1 0.1" type="hinge"/>
						</body>
					</body>
				</body>
			</body>
			<body name="body2" pos="0 0 0" euler="0 0 0">
				<geom name="geombody2" pos="-0.02 0 0" size="0.2 0.4 0.05" type="box" euler="0 0 0"/>
				<joint axis="1 0 0" name="joint_joint6" pos="0 0 0" range="-45 45" type="hinge"/>
				<body name="limbmount5" pos="0.1875 -0.2 0" euler="0 90 0">
					<geom fromto="0 0 0 0.025 0 0" name="geomlimbmount5" size="0.025" type="capsule" euler="0 0 0"/>
					<joint axis="1 0 0" name="joint_joint7" pos="0 0 0" range="-45 45" type="hinge"/>
					<body name="motor22" pos="0 0 0" euler="0 -90 0">
						<geom fromto="0 0 0 0.042 0 0" name="geommotor22" pos="0 0 0" size="0.066" type="cylinder" euler="0 0 0"/>
						<joint axis="1 0 0" name="joint_joint85" pos="0 0 0" range="-45 45" type="hinge"/>
					</body>
					<body name="motor11" pos="0 0 0" euler="0 -90 0">
						<geom fromto="0 0 0 0.042 0 0" name="geommotor11" pos="0 0 0" size="0.066" type="cylinder" euler="0 0 0"/>
						<joint axis="1 0 0" name="joint_joint36" pos="0 0 0" range="-45 45" type="hinge"/>
						<body name="limblink8" pos="0 0 0" euler="0 90 0">
							<geom fromto="0 0 0 0.3 0 0" name="geomlimblink8" size="0.06" type="capsule" euler="0 0 0"/>
							<joint axis="0 1 0" name="joint_joint43" pos="0 0 0" range="-0.1 0.1" type="hinge"/>
						</body>
					</body>
					<body name="motor10" pos="0 0 0" euler="0 -90 0">
						<geom fromto="0 0 0 0.042 0 0" name="geommotor10" pos="0 0 0" size="0.066" type="cylinder" euler="0 0 0"/>
						<joint axis="1 0 0" name="joint_joint35" pos="0 0 0" range="-45 45" type="hinge"/>
						<body name="limblink27" pos="0.015 0 0" euler="0 90 0">
							<geom fromto="0 0 0 0.15 0 0" name="geomlimblink27" size="0.03" type="capsule" euler="0 0 0"/>
							<joint axis="0 1 0" name="joint_joint93" pos="0 0 0" range="-0.1 0.1" type="hinge"/>
						</body>
						<body name="limblink19" pos="0.042 0 0" euler="0 90 0">
							<geom fromto="0 0 0 0.3 0 0" name="geomlimblink19" size="0.06" type="capsule" euler="0 0 0"/>
							<joint axis="0 1 0" name="joint_joint64" pos="0 0 0" range="-0.1 0.1" type="hinge"/>
						</body>
						<body name="limblink7" pos="0.015 0 0" euler="0 90 0">
							<geom fromto="0 0 0 0.15 0 0" name="geomlimblink7" size="0.03" type="capsule" euler="0 0 0"/>
							<joint axis="0 1 0" name="joint_joint40" pos="0 0 0" range="-0.1 0.1" type="hinge"/>
							<body name="leg11" pos="0.6 0 0" euler="0 0 0">
								<geom fromto="0 0 0 0.8 0 0" name="geomleg11" size="0.08" type="capsule" euler="0 0 0"/>
								<joint axis="1 0 0" damping="2.5" name="joint_joint51" pos="0 0 0" range="-0.1 0.1" stiffness="80" type="slide"/>
							</body>
							<body name="leg9" pos="0.6 0 0" euler="0 0 0">
								<geom fromto="0 0 0 0.8 0 0" name="geomleg9" size="0.08" type="capsule" euler="0 0 0"/>
								<joint axis="1 0 0" damping="2.5" name="joint_joint42" pos="0 0 0" range="-0.1 0.1" stiffness="80" type="slide"/>
							</body>
						</body>
					</body>
					<body name="motor9" pos="0 0 0" euler="0 -90 0">
						<geom fromto="0 0 0 0.042 0 0" name="geommotor9" pos="0 0 0" size="0.066" type="cylinder" euler="0 0 0"/>
						<joint axis="1 0 0" name="joint_joint34" pos="0 0 0" range="-45 45" type="hinge"/>
					</body>
				</body>
			</body>
			<body name="body1" pos="0 0 0" euler="0 0 0">
				<geom name="geombody1" pos="-0.02 0 0" size="0.2 0.4 0.05" type="box" euler="0 0 0"/>
				<joint axis="1 0 0" name="joint_joint1" pos="0 0 0" range="-45 45" type="hinge"/>
				<body name="limbmount12" pos="0.1875 0.2 0" euler="0 90 0">
					<geom fromto="0 0 0 0.025 0 0" name="geomlimbmount12" size="0.025" type="capsule" euler="0 0 0"/>
					<joint axis="0 1 0" name="joint_joint87" pos="0 0 0" range="-45 45" type="hinge"/>
				</body>
				<body name="limbmount10" pos="-0.225 -0.2 0" euler="0 90 0">
					<geom fromto="0 0 0 0.025 0 0" name="geomlimbmount10" size="0.025" type="capsule" euler="0 0 0"/>
					<joint axis="1 0 0" name="joint_joint41" pos="0 0 0" range="-45 45" type="hinge"/>
				</body>
				<body name="limbmount8" pos="0.1875 0.2 0" euler="0 90 0">
					<geom fromto="0 0 0 0.025 0 0" name="geomlimbmount8" size="0.025" type="capsule" euler="0 0 0"/>
					<joint axis="0 1 0" name="joint_joint22" pos="0 0 0" range="-45 45" type="hinge"/>
					<body name="motor23" pos="0 0 0" euler="0 -90 0">
						<geom fromto="0 0 0 0.042 0 0" name="geommotor23" pos="0 0 0" size="0.066" type="cylinder" euler="0 0 0"/>
						<joint axis="1 0 0" name="joint_joint94" pos="0 0 0" range="-45 45" type="hinge"/>
					</body>
					<body name="motor19" pos="0 0 0" euler="0 -90 0">
						<geom fromto="0 0 0 0.042 0 0" name="geommotor19" pos="0 0 0" size="0.066" type="cylinder" euler="0 0 0"/>
						<joint axis="1 0 0" name="joint_joint78" pos="0 0 0" range="-45 45" type="hinge"/>
					</body>
					<body name="motor16" pos="0 0 0" euler="0 -90 0">
						<geom fromto="0 0 0 0.042 0 0" name="geommotor16" pos="0 0 0" size="0.066" type="cylinder" euler="0 0 0"/>
						<joint axis="1 0 0" name="joint_joint63" pos="0 0 0" range="-45 45" type="hinge"/>
					</body>
				</body>
				<body name="limbmount7" pos="0.1875 -0.2 0" euler="0 90 0">
					<geom fromto="0 0 0 0.025 0 0" name="geomlimbmount7" size="0.025" type="capsule" euler="0 0 0"/>
					<joint axis="1 0 0" name="joint_joint12" pos="0 0 0" range="-45 45" type="hinge"/>
					<body name="motor13" pos="0 0 0" euler="0 -90 0">
						<geom fromto="0 0 0 0.042 0 0" name="geommotor13" pos="0 0 0" size="0.066" type="cylinder" euler="0 0 0"/>
						<joint axis="1 0 0" name="joint_joint44" pos="0 0 0" range="-45 45" type="hinge"/>
						<body name="limblink16" pos="0 0 0" euler="0 90 0">
							<geom fromto="0 0 0 0.3 0 0" name="geomlimblink16" size="0.06" type="capsule" euler="0 0 0"/>
							<joint axis="0 1 0" name="joint_joint59" pos="0 0 0" range="-0.1 0.1" type="hinge"/>
						</body>
						<body name="limblink13" pos="0.015 0 0" euler="0 90 0">
							<geom fromto="0 0 0 0.15 0 0" name="geomlimblink13" size="0.03" type="capsule" euler="0 0 0"/>
							<joint axis="0 1 0" name="joint_joint53" pos="0 0 0" range="-0.1 0.1" type="hinge"/>
							<body name="leg14" pos="0.6 0 0" euler="0 0 0">
								<geom fromto="0 0 0 0.8 0 0" name="geomleg14" size="0.08" type="capsule" euler="0 0 0"/>
								<joint axis="1 0 0" damping="2.5" name="joint_joint62" pos="0 0 0" range="-0.1 0.1" stiffness="80" type="slide"/>
							</body>
						</body>
					</body>
				</body>
				<body name="limbmount6" pos="0.1875 0.2 0" euler="0 90 0">
					<geom fromto="0 0 0 0.025 0 0" name="geomlimbmount6" size="0.025" type="capsule" euler="0 0 0"/>
					<joint axis="0 1 0" name="joint_joint9" pos="0 0 0" range="-45 45" type="hinge"/>
					<body name="motor12" pos="0 0 0" euler="0 -90 0">
						<geom fromto="0 0 0 0.042 0 0" name="geommotor12" pos="0 0 0" size="0.066" type="cylinder" euler="0 0 0"/>
						<joint axis="1 0 0" name="joint_joint39" pos="0 0 0" range="-45 45" type="hinge"/>
					</body>
				</body>
				<body name="limbmount4" pos="0.1875 -0.2 0" euler="0 90 0">
					<geom fromto="0 0 0 0.025 0 0" name="geomlimbmount4" size="0.025" type="capsule" euler="0 0 0"/>
					<joint axis="1 0 0" name="joint_joint5" pos="0 0 0" range="-45 45" type="hinge"/>
					<body name="motor18" pos="0 0 0" euler="0 -90 0">
						<geom fromto="0 0 0 0.042 0 0" name="geommotor18" pos="0 0 0" size="0.066" type="cylinder" euler="0 0 0"/>
						<joint axis="1 0 0" name="joint_joint75" pos="0 0 0" range="-45 45" type="hinge"/>
					</body>
					<body name="motor15" pos="0 0 0" euler="0 -90 0">
						<geom fromto="0 0 0 0.042 0 0" name="geommotor15" pos="0 0 0" size="0.066" type="cylinder" euler="0 0 0"/>
						<joint axis="1 0 0" name="joint_joint50" pos="0 0 0" range="-45 45" type="hinge"/>
						<body name="limblink26" pos="0 0 0" euler="0 90 0">
							<geom fromto="0 0 0 0.3 0 0" name="geomlimblink26" size="0.06" type="capsule" euler="0 0 0"/>
							<joint axis="0 1 0" name="joint_joint91" pos="0 0 0" range="-0.1 0.1" type="hinge"/>
						</body>
						<body name="limblink17" pos="0.015 0 0" euler="0 90 0">
							<geom fromto="0 0 0 0.15 0 0" name="geomlimblink17" size="0.03" type="capsule" euler="0 0 0"/>
							<joint axis="0 1 0" name="joint_joint60" pos="0 0 0" range="-0.1 0.1" type="hinge"/>
							<body name="leg19" pos="0.6 0 0" euler="0 0 0">
								<geom fromto="0 0 0 0.8 0 0" name="geomleg19" size="0.08" type="capsule" euler="0 0 0"/>
								<joint axis="1 0 0" damping="2.5" name="joint_joint77" pos="0 0 0" range="-0.1 0.1" stiffness="80" type="slide"/>
							</body>
						</body>
					</body>
					<body name="motor4" pos="0 0 0" euler="0 -90 0">
						<geom fromto="0 0 0 0.042 0 0" name="geommotor4" pos="0 0 0" size="0.066" type="cylinder" euler="0 0 0"/>
						<joint axis="1 0 0" name="joint_joint16" pos="0 0 0" range="-45 45" type="hinge"/>
						<body name="limblink25" pos="0.042 0 0" euler="0 90 0">
							<geom fromto="0 0 0 0.3 0 0" name="geomlimblink25" size="0.03" type="capsule" euler="0 0 0"/>
							<joint axis="0 1 0" name="joint_joint89" pos="0 0 0" range="-0.1 0.1" type="hinge"/>
						</body>
						<body name="limblink23" pos="0 0 0" euler="0 90 0">
							<geom fromto="0 0 0 0.3 0 0" name="geomlimblink23" size="0.06" type="capsule" euler="0 0 0"/>
							<joint axis="0 1 0" name="joint_joint74" pos="0 0 0" range="-0.1 0.1" type="hinge"/>
						</body>
						<body name="limblink15" pos="0.042 0 0" euler="0 90 0">
							<geom fromto="0 0 0 0.3 0 0" name="geomlimblink15" size="0.03" type="capsule" euler="0 0 0"/>
							<joint axis="0 1 0" name="joint_joint58" pos="0 0 0" range="-0.1 0.1" type="hinge"/>
						</body>
					</body>
					<body name="motor3" pos="0 0 0" euler="0 -90 0">
						<geom fromto="0 0 0 0.042 0 0" name="geommotor3" pos="0 0 0" size="0.066" type="cylinder" euler="0 0 0"/>
						<joint axis="1 0 0" name="joint_joint14" pos="0 0 0" range="-45 45" type="hinge"/>
						<body name="limblink11" pos="0 0 0" euler="0 90 0">
							<geom fromto="0 0 0 0.3 0 0" name="geomlimblink11" size="0.06" type="capsule" euler="0 0 0"/>
							<joint axis="0 1 0" name="joint_joint49" pos="0 0 0" range="-0.1 0.1" type="hinge"/>
							<body name="leg13" pos="0.6 0 0" euler="0 0 0">
								<geom fromto="0 0 0 0.8 0 0" name="geomleg13" size="0.08" type="capsule" euler="0 0 0"/>
								<joint axis="1 0 0" damping="2.5" name="joint_joint56" pos="0 0 0" range="-0.1 0.1" stiffness="80" type="slide"/>
							</body>
						</body>
					</body>
					<body name="motor2" pos="0 0 0" euler="0 -90 0">
						<geom fromto="0 0 0 0.042 0 0" name="geommotor2" pos="0 0 0" size="0.066" type="cylinder" euler="0 0 0"/>
						<joint axis="1 0 0" name="joint_joint11" pos="0 0 0" range="-45 45" type="hinge"/>
						<body name="limblink9" pos="0 0 0" euler="0 90 0">
							<geom fromto="0 0 0 0.3 0 0" name="geomlimblink9" size="0.06" type="capsule" euler="0 0 0"/>
							<joint axis="0 1 0" name="joint_joint45" pos="0 0 0" range="-0.1 0.1" type="hinge"/>
						</body>
						<body name="limblink3" pos="0 0 0" euler="0 90 0">
							<geom fromto="0 0 0 0.3 0 0" name="geomlimblink3" size="0.06" type="capsule" euler="0 0 0"/>
							<joint axis="0 1 0" name="joint_joint19" pos="0 0 0" range="-0.1 0.1" type="hinge"/>
						</body>
					</body>
				</body>
				<body name="limbmount3" pos="-0.225 -0.2 0" euler="0 90 0">
					<geom fromto="0 0 0 0.025 0 0" name="geomlimbmount3" size="0.025" type="capsule" euler="0 0 0"/>
					<joint axis="1 0 0" name="joint_joint4" pos="0 0 0" range="-45 45" type="hinge"/>
					<body name="motor17" pos="0 0 0" euler="0 -90 0">
						<geom fromto="0 0 0 0.042 0 0" name="geommotor17" pos="0 0 0" size="0.066" type="cylinder" euler="0 0 0"/>
						<joint axis="1 0 0" name="joint_joint73" pos="0 0 0" range="-45 45" type="hinge"/>
						<body name="limblink24" pos="0.015 0 0" euler="0 90 0">
							<geom fromto="0 0 0 0.15 0 0" name="geomlimblink24" size="0.03" type="capsule" euler="0 0 0"/>
							<joint axis="0 1 0" name="joint_joint76" pos="0 0 0" range="-0.1 0.1" type="hinge"/>
							<body name="leg21" pos="0.6 0 0" euler="0 0 0">
								<geom fromto="0 0 0 0.8 0 0" name="geomleg21" size="0.08" type="capsule" euler="0 0 0"/>
								<joint axis="1 0 0" damping="2.5" name="joint_joint86" pos="0 0 0" range="-0.1 0.1" stiffness="80" type="slide"/>
							</body>
						</body>
					</body>
					<body name="motor6" pos="0 0 0" euler="0 -90 0">
						<geom fromto="0 0 0 0.042 0 0" name="geommotor6" pos="0 0 0" size="0.066" type="cylinder" euler="0 0 0"/>
						<joint axis="1 0 0" name="joint_joint25" pos="0 0 0" range="-45 45" type="hinge"/>
						<body name="limblink12" pos="0.042 0 0" euler="0 90 0">
							<geom fromto="0 0 0 0.3 0 0" name="geomlimblink12" size="0.03" type="capsule" euler="0 0 0"/>
							<joint axis="0 1 0" name="joint_joint52" pos="0 0 0" range="-0.1 0.1" type="hinge"/>
						</body>
					</body>
					<body name="motor5" pos="0 0 0" euler="0 -90 0">
						<geom fromto="0 0 0 0.042 0 0" name="geommotor5" pos="0 0 0" size="0.066" type="cylinder" euler="0 0 0"/>
						<joint axis="1 0 0" name="joint_joint17" pos="0 0 0" range="-45 45" type="hinge"/>
						<body name="limblink14" pos="0.042 0 0" euler="0 90 0">
							<geom fromto="0 0 0 0.3 0 0" name="geomlimblink14" size="0.03" type="capsule" euler="0 0 0"/>
							<joint axis="0 1 0" name="joint_joint55" pos="0 0 0" range="-0.1 0.1" type="hinge"/>
							<body name="leg15" pos="0.6 0 0" euler="0 0 0">
								<geom fromto="0 0 0 0.8 0 0" name="geomleg15" size="0.08" type="capsule" euler="0 0 0"/>
								<joint axis="1 0 0" damping="2.5" name="joint_joint67" pos="0 0 0" range="-0.1 0.1" stiffness="80" type="slide"/>
							</body>
						</body>
						<body name="limblink4" pos="0 0 0" euler="0 90 0">
							<geom fromto="0 0 0 0.3 0 0" name="geomlimblink4" size="0.06" type="capsule" euler="0 0 0"/>
							<joint axis="0 1 0" name="joint_joint23" pos="0 0 0" range="-0.1 0.1" type="hinge"/>
							<body name="leg6" pos="0.6 0 0" euler="0 0 0">
								<geom fromto="0 0 0 0.8 0 0" name="geomleg6" size="0.08" type="capsule" euler="0 0 0"/>
								<joint axis="1 0 0" damping="2.5" name="joint_joint30" pos="0 0 0" range="-0.1 0.1" stiffness="80" type="slide"/>
							</body>
							<body name="leg5" pos="0.6 0 0" euler="0 0 0">
								<geom fromto="0 0 0 0.8 0 0" name="geomleg5" size="0.08" type="capsule" euler="0 0 0"/>
								<joint axis="1 0 0" damping="2.5" name="joint_joint29" pos="0 0 0" range="-0.1 0.1" stiffness="80" type="slide"/>
							</body>
						</body>
					</body>
				</body>
				<body name="limbmount2" pos="-0.225 0.2 0" euler="0 90 0">
					<geom fromto="0 0 0 0.025 0 0" name="geomlimbmount2" size="0.025" type="capsule" euler="0 0 0"/>
					<joint axis="1 0 0" name="joint_joint3" pos="0 0 0" range="-45 45" type="hinge"/>
					<body name="motor21" pos="0 0 0" euler="0 -90 0">
						<geom fromto="0 0 0 0.042 0 0" name="geommotor21" pos="0 0 0" size="0.066" type="cylinder" euler="0 0 0"/>
						<joint axis="1 0 0" name="joint_joint84" pos="0 0 0" range="-45 45" type="hinge"/>
					</body>
				</body>
				<body name="limbmount1" pos="0.1875 0.2 0" euler="0 90 0">
					<geom fromto="0 0 0 0.025 0 0" name="geomlimbmount1" size="0.025" type="capsule" euler="0 0 0"/>
					<joint axis="0 1 0" name="joint_joint2" pos="0 0 0" range="-45 45" type="hinge"/>
					<body name="motor20" pos="0 0 0" euler="0 -90 0">
						<geom fromto="0 0 0 0.042 0 0" name="geommotor20" pos="0 0 0" size="0.066" type="cylinder" euler="0 0 0"/>
						<joint axis="1 0 0" name="joint_joint83" pos="0 0 0" range="-45 45" type="hinge"/>
					</body>
					<body name="motor7" pos="0 0 0" euler="0 -90 0">
						<geom fromto="0 0 0 0.042 0 0" name="geommotor7" pos="0 0 0" size="0.066" type="cylinder" euler="0 0 0"/>
						<joint axis="1 0 0" name="joint_joint26" pos="0 0 0" range="-45 45" type="hinge"/>
						<body name="limblink22" pos="0.042 0 0" euler="0 90 0">
							<geom fromto="0 0 0 0.3 0 0" name="geomlimblink22" size="0.06" type="capsule" euler="0 0 0"/>
							<joint axis="0 1 0" name="joint_joint72" pos="0 0 0" range="-0.1 0.1" type="hinge"/>
							<body name="leg23" pos="0.6 0 0" euler="0 0 0">
								<geom fromto="0 0 0 0.8 0 0" name="geomleg23" size="0.08" type="capsule" euler="0 0 0"/>
								<joint axis="1 0 0" damping="2.5" name="joint_joint90" pos="0 0 0" range="-0.1 0.1" stiffness="80" type="slide"/>
							</body>
						</body>
						<body name="limblink6" pos="0.042 0 0" euler="0 90 0">
							<geom fromto="0 0 0 0.3 0 0" name="geomlimblink6" size="0.03" type="capsule" euler="0 0 0"/>
							<joint axis="0 1 0" name="joint_joint38" pos="0 0 0" range="-0.1 0.1" type="hinge"/>
						</body>
						<body name="limblink5" pos="0.015 0 0" euler="0 90 0">
							<geom fromto="0 0 0 0.15 0 0" name="geomlimblink5" size="0.03" type="capsule" euler="0 0 0"/>
							<joint axis="0 1 0" name="joint_joint27" pos="0 0 0" range="-0.1 0.1" type="hinge"/>
							<body name="leg18" pos="0.6 0 0" euler="0 0 0">
								<geom fromto="0 0 0 0.8 0 0" name="geomleg18" size="0.08" type="capsule" euler="0 0 0"/>
								<joint axis="1 0 0" damping="2.5" name="joint_joint71" pos="0 0 0" range="-0.1 0.1" stiffness="80" type="slide"/>
							</body>
							<body name="leg10" pos="0.6 0 0" euler="0 0 0">
								<geom fromto="0 0 0 0.8 0 0" name="geomleg10" size="0.08" type="capsule" euler="0 0 0"/>
								<joint axis="1 0 0" damping="2.5" name="joint_joint48" pos="0 0 0" range="-0.1 0.1" stiffness="80" type="slide"/>
							</body>
							<body name="leg8" pos="0.6 0 0" euler="0 0 0">
								<geom fromto="0 0 0 0.8 0 0" name="geomleg8" size="0.08" type="capsule" euler="0 0 0"/>
								<joint axis="1 0 0" damping="2.5" name="joint_joint37" pos="0 0 0" range="-0.1 0.1" stiffness="80" type="slide"/>
							</body>
						</body>
					</body>
					<body name="motor1" pos="0 0 0" euler="0 -90 0">
						<geom fromto="0 0 0 0.042 0 0" name="geommotor1" pos="0 0 0" size="0.066" type="cylinder" euler="0 0 0"/>
						<joint axis="1 0 0" name="joint_joint10" pos="0 0 0" range="-45 45" type="hinge"/>
						<body name="limblink2" pos="0.042 0 0" euler="0 90 0">
							<geom fromto="0 0 0 0.3 0 0" name="geomlimblink2" size="0.03" type="capsule" euler="0 0 0"/>
							<joint axis="0 1 0" name="joint_joint18" pos="0 0 0" range="-0.1 0.1" type="hinge"/>
							<body name="leg24" pos="0.6 0 0" euler="0 0 0">
								<geom fromto="0 0 0 0.8 0 0" name="geomleg24" size="0.08" type="capsule" euler="0 0 0"/>
								<joint axis="1 0 0" damping="2.5" name="joint_joint92" pos="0 0 0" range="-0.1 0.1" stiffness="80" type="slide"/>
							</body>
							<body name="leg12" pos="0.6 0 0" euler="0 0 0">
								<geom fromto="0 0 0 0.8 0 0" name="geomleg12" size="0.08" type="capsule" euler="0 0 0"/>
								<joint axis="1 0 0" damping="2.5" name="joint_joint54" pos="0 0 0" range="-0.1 0.1" stiffness="80" type="slide"/>
							</body>
							<body name="leg3" pos="0.6 0 0" euler="0 0 0">
								<geom fromto="0 0 0 0.8 0 0" name="geomleg3" size="0.08" type="capsule" euler="0 0 0"/>
								<joint axis="1 0 0" damping="2.5" name="joint_joint21" pos="0 0 0" range="-0.1 0.1" stiffness="80" type="slide"/>
							</body>
						</body>
						<body name="limblink1" pos="0.042 0 0" euler="0 90 0">
							<geom fromto="0 0 0 0.3 0 0" name="geomlimblink1" size="0.03" type="capsule" euler="0 0 0"/>
							<joint axis="0 1 0" name="joint_joint13" pos="0 0 0" range="-0.1 0.1" type="hinge"/>
							<body name="leg22" pos="0.6 0 0" euler="0 0 0">
								<geom fromto="0 0 0 0.8 0 0" name="geomleg22" size="0.08" type="capsule" euler="0 0 0"/>
								<joint axis="1 0 0" damping="2.5" name="joint_joint88" pos="0 0 0" range="-0.1 0.1" stiffness="80" type="slide"/>
							</body>
							<body name="leg20" pos="0.6 0 0" euler="0 0 0">
								<geom fromto="0 0 0 0.8 0 0" name="geomleg20" size="0.08" type="capsule" euler="0 0 0"/>
								<joint axis="1 0 0" damping="2.5" name="joint_joint82" pos="0 0 0" range="-0.1 0.1" stiffness="80" type="slide"/>
							</body>
							<body name="leg7" pos="0.6 0 0" euler="0 0 0">
								<geom fromto="0 0 0 0.8 0 0" name="geomleg7" size="0.08" type="capsule" euler="0 0 0"/>
								<joint axis="1 0 0" damping="2.5" name="joint_joint33" pos="0 0 0" range="-0.1 0.1" stiffness="80" type="slide"/>
							</body>
							<body name="leg4" pos="0.6 0 0" euler="0 0 0">
								<geom fromto="0 0 0 0.8 0 0" name="geomleg4" size="0.08" type="capsule" euler="0 0 0"/>
								<joint axis="1 0 0" damping="2.5" name="joint_joint28" pos="0 0 0" range="-0.1 0.1" stiffness="80" type="slide"/>
							</body>
							<body name="leg2" pos="0.6 0 0" euler="0 0 0">
								<geom fromto="0 0 0 0.8 0 0" name="geomleg2" size="0.08" type="capsule" euler="0 0 0"/>
								<joint axis="1 0 0" damping="2.5" name="joint_joint20" pos="0 0 0" range="-0.1 0.1" stiffness="80" type="slide"/>
							</body>
							<body name="leg1" pos="0.6 0 0" euler="0 0 0">
								<geom fromto="0 0 0 0.8 0 0" name="geomleg1" size="0.08" type="capsule" euler="0 0 0"/>
								<joint axis="1 0 0" damping="2.5" name="joint_joint15" pos="0 0 0" range="-0.1 0.1" stiffness="80" type="slide"/>
							</body>
						</body>
					</body>
				</body>
			</body>
		</body>
	</worldbody>
	<actuator>
		<motor ctrllimited="true" ctrlrange="-1 1" joint="joint_joint80"/>
		<motor ctrllimited="true" ctrlrange="-1 1" joint="joint_joint79"/>
		<motor ctrllimited="true" ctrlrange="-1 1" joint="joint_joint65"/>
		<motor ctrllimited="true" ctrlrange="-1 1" joint="joint_joint57"/>
		<motor ctrllimited="true" ctrlrange="-1 1" joint="joint_joint81"/>
		<motor ctrllimited="true" ctrlrange="-1 1" joint="joint_joint31"/>
		<motor ctrllimited="true" ctrlrange="-1 1" joint="joint_joint8"/>
		<motor ctrllimited="true" ctrlrange="-1 1" joint="joint_joint24"/>
		<motor ctrllimited="true" ctrlrange="-1.2 1.2" joint="joint_joint46"/>
		<motor ctrllimited="true" ctrlrange="-1 1" joint="joint_joint66"/>
		<motor ctrllimited="true" ctrlrange="-1 1" joint="joint_joint70"/>
		<motor ctrllimited="true" ctrlrange="-1 1" joint="joint_joint47"/>
		<motor ctrllimited="true" ctrlrange="-1.2 1.2" joint="joint_joint32"/>
		<motor ctrllimited="true" ctrlrange="-1 1" joint="joint_joint68"/>
		<motor ctrllimited="true" ctrlrange="-1 1" joint="joint_joint69"/>
		<motor ctrllimited="true" ctrlrange="-1 1" joint="joint_joint61"/>
		<motor ctrllimited="true" ctrlrange="-1 1" joint="joint_joint6"/>
		<motor ctrllimited="true" ctrlrange="-1 1" joint="joint_joint7"/>
		<motor ctrllimited="true" ctrlrange="-1.2 1.2" joint="joint_joint85"/>
		<motor ctrllimited="true" ctrlrange="-1.2 1.2" joint="joint_joint36"/>
		<motor ctrllimited="true" ctrlrange="-1 1" joint="joint_joint43"/>
		<motor ctrllimited="true" ctrlrange="-1.2 1.2" joint="joint_joint35"/>
		<motor ctrllimited="true" ctrlrange="-1 1" joint="joint_joint93"/>
		<motor ctrllimited="true" ctrlrange="-1 1" joint="joint_joint64"/>
		<motor ctrllimited="true" ctrlrange="-1 1" joint="joint_joint40"/>
		<motor ctrllimited="true" ctrlrange="-1 1" joint="joint_joint51"/>
		<motor ctrllimited="true" ctrlrange="-1 1" joint="joint_joint42"/>
		<motor ctrllimited="true" ctrlrange="-1.2 1.2" joint="joint_joint34"/>
		<motor ctrllimited="true" ctrlrange="-1 1" joint="joint_joint1"/>
		<motor ctrllimited="true" ctrlrange="-1 1" joint="joint_joint87"/>
		<motor ctrllimited="true" ctrlrange="-1 1" joint="joint_joint41"/>
		<motor ctrllimited="true" ctrlrange="-1 1" joint="joint_joint22"/>
		<motor ctrllimited="true" ctrlrange="-1.2 1.2" joint="joint_joint94"/>
		<motor ctrllimited="true" ctrlrange="-1.2 1.2" joint="joint_joint78"/>
		<motor ctrllimited="true" ctrlrange="-1.2 1.2" joint="joint_joint63"/>
		<motor ctrllimited="true" ctrlrange="-1 1" joint="joint_joint12"/>
		<motor ctrllimited="true" ctrlrange="-1.2 1.2" joint="joint_joint44"/>
		<motor ctrllimited="true" ctrlrange="-1 1" joint="joint_joint59"/>
		<motor ctrllimited="true" ctrlrange="-1 1" joint="joint_joint53"/>
		<motor ctrllimited="true" ctrlrange="-1 1" joint="joint_joint62"/>
		<motor ctrllimited="true" ctrlrange="-1 1" joint="joint_joint9"/>
		<motor ctrllimited="true" ctrlrange="-1.2 1.2" joint="joint_joint39"/>
		<motor ctrllimited="true" ctrlrange="-1 1" joint="joint_joint5"/>
		<motor ctrllimited="true" ctrlrange="-1.2 1.2" joint="joint_joint75"/>
		<motor ctrllimited="true" ctrlrange="-1.2 1.2" joint="joint_joint50"/>
		<motor ctrllimited="true" ctrlrange="-1 1" joint="joint_joint91"/>
		<motor ctrllimited="true" ctrlrange="-1 1" joint="joint_joint60"/>
		<motor ctrllimited="true" ctrlrange="-1 1" joint="joint_joint77"/>
		<motor ctrllimited="true" ctrlrange="-1.2 1.2" joint="joint_joint16"/>
		<motor ctrllimited="true" ctrlrange="-1 1" joint="joint_joint89"/>
		<motor ctrllimited="true" ctrlrange="-1 1" joint="joint_joint74"/>
		<motor ctrllimited="true" ctrlrange="-1 1" joint="joint_joint58"/>
		<motor ctrllimited="true" ctrlrange="-1.2 1.2" joint="joint_joint14"/>
		<motor ctrllimited="true" ctrlrange="-1 1" joint="joint_joint49"/>
		<motor ctrllimited="true" ctrlrange="-1 1" joint="joint_joint56"/>
		<motor ctrllimited="true" ctrlrange="-1.2 1.2" joint="joint_joint11"/>
		<motor ctrllimited="true" ctrlrange="-1 1" joint="joint_joint45"/>
		<motor ctrllimited="true" ctrlrange="-1 1" joint="joint_joint19"/>
		<motor ctrllimited="true" ctrlrange="-1 1" joint="joint_joint4"/>
		<motor ctrllimited="true" ctrlrange="-1.2 1.2" joint="joint_joint73"/>
		<motor ctrllimited="true" ctrlrange="-1 1" joint="joint_joint76"/>
		<motor ctrllimited="true" ctrlrange="-1 1" joint="joint_joint86"/>
		<motor ctrllimited="true" ctrlrange="-1.2 1.2" joint="joint_joint25"/>
		<motor ctrllimited="true" ctrlrange="-1 1" joint="joint_joint52"/>
		<motor ctrllimited="true" ctrlrange="-1.2 1.2" joint="joint_joint17"/>
		<motor ctrllimited="true" ctrlrange="-1 1" joint="joint_joint55"/>
		<motor ctrllimited="true" ctrlrange="-1 1" joint="joint_joint67"/>
		<motor ctrllimited="true" ctrlrange="-1 1" joint="joint_joint23"/>
		<motor ctrllimited="true" ctrlrange="-1 1" joint="joint_joint30"/>
		<motor ctrllimited="true" ctrlrange="-1 1" joint="joint_joint29"/>
		<motor ctrllimited="true" ctrlrange="-1 1" joint="joint_joint3"/>
		<motor ctrllimited="true" ctrlrange="-1.2 1.2" joint="joint_joint84"/>
		<motor ctrllimited="true" ctrlrange="-1 1" joint="joint_joint2"/>
		<motor ctrllimited="true" ctrlrange="-1.2 1.2" joint="joint_joint83"/>
		<motor ctrllimited="true" ctrlrange="-1.2 1.2" joint="joint_joint26"/>
		<motor ctrllimited="true" ctrlrange="-1 1" joint="joint_joint72"/>
		<motor ctrllimited="true" ctrlrange="-1 1" joint="joint_joint90"/>
		<motor ctrllimited="true" ctrlrange="-1 1" joint="joint_joint38"/>
		<motor ctrllimited="true" ctrlrange="-1 1" joint="joint_joint27"/>
		<motor ctrllimited="true" ctrlrange="-1 1" joint="joint_joint71"/>
		<motor ctrllimited="true" ctrlrange="-1 1" joint="joint_joint48"/>
		<motor ctrllimited="true" ctrlrange="-1 1" joint="joint_joint37"/>
		<motor ctrllimited="true" ctrlrange="-1.2 1.2" joint="joint_joint10"/>
		<motor ctrllimited="true" ctrlrange="-1 1" joint="joint_joint18"/>
		<motor ctrllimited="true" ctrlrange="-1 1" joint="joint_joint92"/>
		<motor ctrllimited="true" ctrlrange="-1 1" joint="joint_joint54"/>
		<motor ctrllimited="true" ctrlrange="-1 1" joint="joint_joint21"/>
		<motor ctrllimited="true" ctrlrange="-1 1" joint="joint_joint13"/>
		<motor ctrllimited="true" ctrlrange="-1 1" joint="joint_joint88"/>
		<motor ctrllimited="true" ctrlrange="-1 1" joint="joint_joint82"/>
		<motor ctrllimited="true" ctrlrange="-1 1" joint="joint_joint33"/>
		<motor ctrllimited="true" ctrlrange="-1 1" joint="joint_joint28"/>
		<motor ctrllimited="true" ctrlrange="-1 1" joint="joint_joint20"/>
		<motor ctrllimited="true" ctrlrange="-1 1" joint="joint_joint15"/>
	</actuator>
</mujoco>