<mujoco model="xmlrobot">
	<compiler />
	<option gravity="0 0 0" />
	<size nconmax="500" njmax="1000" />
	<custom />
	<default>
		<joint armature="1" damping="1" limited="true" />
		<geom conaffinity="0" condim="3" margin="0.01" rgba="0.8 0.6 0.4 1" />
	</default>
	<asset>
		<texture builtin="gradient" height="100" rgb1="1 1 1" rgb2="0 0 0" type="skybox" width="100" />
		<texture builtin="flat" height="1278" mark="cross" markrgb="1 1 1" name="texgeom" random="0.01" rgb1="0.8 0.6 0.4" rgb2="0.8 0.6 0.4" type="cube" width="127" />
		<texture builtin="checker" height="100" name="texplane" rgb1="0 0 0" rgb2="0.8 0.8 0.8" type="2d" width="100" />
		<material name="MatPlane" reflectance="0.5" shininess="1" specular="1" texrepeat="60 60" texture="texplane" />
		<material name="geom" texture="texgeom" texuniform="true" />
	</asset>
	<worldbody>
		<light cutoff="100" diffuse="1 1 1" dir="0 0 -1.3" directional="true" exponent="1" pos="0 0 1.3" specular="0.1 0.1 0.1" />
		<geom conaffinity="1" condim="3" material="MatPlane" name="floor" pos="0 0 0" rgba="0.8 0.9 0.8 1" size="40 40 40" type="plane" />
		<body euler="0 0 0" name="root" pos="0 0 2">
			<geom euler="0 0 0" name="geomroot" pos="0 0 2" size="0.0005" type="sphere" />
			<body euler="0 0 0" name="body1" pos="0 0 0">
				<geom euler="0 0 0" name="geombody1" pos="-0.02 0 0" size="0.2 0.4 0.05" type="box" />
				<joint axis="1 0 0" name="joint_joint1" pos="0 0 0" range="-45 45" type="hinge" />
				<body euler="0 90 0" name="limbmount4" pos="0.1875 -0.2 0">
					<geom euler="0 0 0" fromto="0 0 0 0.025 0 0" name="geomlimbmount4" size="0.025" type="capsule" />
					<joint axis="1 0 0" name="joint_joint19" pos="0 0 0" range="-45 45" type="hinge" />
					<body euler="0 -90 0" name="motor_60208" pos="0 0 0">
						<geom euler="0 0 0" fromto="0 0 0 0.042 0 0" name="geommotor_60208" pos="0 0 0" size="0.066" type="cylinder" />
						<joint axis="1 0 0" name="joint_joint20" pos="0 0 0" range="-45 45" type="hinge" />
						<body euler="0 90 0" name="limblink8" pos="0 0 0">
							<geom euler="0 0 0" fromto="0 0 0 0.3 0 0" name="geomlimblink8" size="0.06" type="capsule" />
							<joint axis="0 1 0" name="joint_joint21" pos="0 0 0" range="-0.1 0.1" type="hinge" />
							<body euler="0 -90 0" name="motor_60209" pos="0.3 0 0">
								<geom euler="0 0 0" fromto="0 0 0 0.042 0 0" name="geommotor_60209" pos="0 0 0" size="0.066" type="cylinder" />
								<joint axis="1 0 0" name="joint_joint22" pos="0 0 0" range="-45 45" type="hinge" />
								<body euler="0 90 0" name="limblink9" pos="0.042 0 0">
									<geom euler="0 0 0" fromto="0 0 0 0.3 0 0" name="geomlimblink9" size="0.03" type="capsule" />
									<joint axis="0 1 0" name="joint_joint23" pos="0 0 0" range="-0.1 0.1" type="hinge" />
									<body euler="0 -90 0" name="motor_602010" pos="0.3 0 0">
										<geom euler="0 0 0" fromto="0 0 0 0.042 0 0" name="geommotor_602010" pos="0 0 0" size="0.066" type="cylinder" />
										<joint axis="1 0 0" name="joint_joint24" pos="0 0 0" range="-45 45" type="hinge" />
										<body euler="0 90 0" name="limblink10" pos="0.015 0 0">
											<geom euler="0 0 0" fromto="0 0 0 0.15 0 0" name="geomlimblink10" size="0.03" type="capsule" />
											<joint axis="0 1 0" name="joint_joint25" pos="0 0 0" range="-0.1 0.1" type="hinge" />
										</body>
									</body>
								</body>
							</body>
						</body>
					</body>
				</body>
				<body euler="0 90 0" name="limbmount3" pos="-0.225 -0.2 0">
					<geom euler="0.0 0.0 180.0" fromto="0 0 0 0.025 0 0" name="geomlimbmount3" size="0.025" type="capsule" />
					<joint axis="1 0 0" name="joint_joint12" pos="0 0 0" range="-45 45" type="hinge" />
					<body euler="0.0 -90.0 180.0" name="motor_60205" pos="0 0 0">
						<geom euler="0 0 0" fromto="0 0 0 0.042 0 0" name="geommotor_60205" pos="0 0 0" size="0.066" type="cylinder" />
						<joint axis="1 0 0" name="joint_joint13" pos="0 0 0" range="-45 45" type="hinge" />
						<body euler="0 90 0" name="limblink5" pos="0 0 0">
							<geom euler="0 0 0" fromto="0 0 0 0.3 0 0" name="geomlimblink5" size="0.06" type="capsule" />
							<joint axis="0 1 0" name="joint_joint14" pos="0 0 0" range="-0.1 0.1" type="hinge" />
							<body euler="0 -90 0" name="motor_60206" pos="0.3 0 0">
								<geom euler="0 0 0" fromto="0 0 0 0.042 0 0" name="geommotor_60206" pos="0 0 0" size="0.066" type="cylinder" />
								<joint axis="1 0 0" name="joint_joint15" pos="0 0 0" range="-45 45" type="hinge" />
								<body euler="0 90 0" name="limblink6" pos="0.042 0 0">
									<geom euler="0 0 0" fromto="0 0 0 0.3 0 0" name="geomlimblink6" size="0.03" type="capsule" />
									<joint axis="0 1 0" name="joint_joint16" pos="0 0 0" range="-0.1 0.1" type="hinge" />
									<body euler="0 -90 0" name="motor_60207" pos="0.3 0 0">
										<geom euler="0 0 0" fromto="0 0 0 0.042 0 0" name="geommotor_60207" pos="0 0 0" size="0.066" type="cylinder" />
										<joint axis="1 0 0" name="joint_joint17" pos="0 0 0" range="-45 45" type="hinge" />
										<body euler="0 90 0" name="limblink7" pos="0.015 0 0">
											<geom euler="0 0 0" fromto="0 0 0 0.15 0 0" name="geomlimblink7" size="0.03" type="capsule" />
											<joint axis="0 1 0" name="joint_joint18" pos="0 0 0" range="-0.1 0.1" type="hinge" />
										</body>
									</body>
								</body>
							</body>
						</body>
					</body>
				</body>
				<body euler="0 90 0" name="limbmount2" pos="-0.225 0.2 0">
					<geom euler="0.0 0.0 180.0" fromto="0 0 0 0.025 0 0" name="geomlimbmount2" size="0.025" type="capsule" />
					<joint axis="1 0 0" name="joint_joint7" pos="0 0 0" range="-45 45" type="hinge" />
					<body euler="0.0 -90.0 180.0" name="motor_60203" pos="0 0 0">
						<geom euler="0 0 0" fromto="0 0 0 0.042 0 0" name="geommotor_60203" pos="0 0 0" size="0.066" type="cylinder" />
						<joint axis="1 0 0" name="joint_joint8" pos="0 0 0" range="-45 45" type="hinge" />
						<body euler="0 90 0" name="limblink3" pos="0 0 0">
							<geom euler="0 0 0" fromto="0 0 0 0.3 0 0" name="geomlimblink3" size="0.06" type="capsule" />
							<joint axis="0 1 0" name="joint_joint9" pos="0 0 0" range="-0.1 0.1" type="hinge" />
							<body euler="0 -90 0" name="motor_60204" pos="0.3 0 0">
								<geom euler="0 0 0" fromto="0 0 0 0.042 0 0" name="geommotor_60204" pos="0 0 0" size="0.066" type="cylinder" />
								<joint axis="1 0 0" name="joint_joint10" pos="0 0 0" range="-45 45" type="hinge" />
								<body euler="0 90 0" name="limblink4" pos="0.015 0 0">
									<geom euler="0 0 0" fromto="0 0 0 0.15 0 0" name="geomlimblink4" size="0.03" type="capsule" />
									<joint axis="0 1 0" name="joint_joint11" pos="0 0 0" range="-0.1 0.1" type="hinge" />
								</body>
							</body>
						</body>
					</body>
				</body>
				<body euler="0 90 0" name="limbmount1" pos="0.1875 0.2 0">
					<geom euler="0 0 0" fromto="0 0 0 0.025 0 0" name="geomlimbmount1" size="0.025" type="capsule" />
					<joint axis="0 1 0" name="joint_joint2" pos="0 0 0" range="-45 45" type="hinge" />
					<body euler="0 -90 0" name="motor_60201" pos="0 0 0">
						<geom euler="0 0 0" fromto="0 0 0 0.042 0 0" name="geommotor_60201" pos="0 0 0" size="0.066" type="cylinder" />
						<joint axis="1 0 0" name="joint_joint3" pos="0 0 0" range="-45 45" type="hinge" />
						<body euler="0 90 0" name="limblink1" pos="0 0 0">
							<geom euler="0 0 0" fromto="0 0 0 0.3 0 0" name="geomlimblink1" size="0.06" type="capsule" />
							<joint axis="0 1 0" name="joint_joint4" pos="0 0 0" range="-0.1 0.1" type="hinge" />
							<body euler="0 -90 0" name="motor_60202" pos="0.3 0 0">
								<geom euler="0 0 0" fromto="0 0 0 0.042 0 0" name="geommotor_60202" pos="0 0 0" size="0.066" type="cylinder" />
								<joint axis="1 0 0" name="joint_joint5" pos="0 0 0" range="-45 45" type="hinge" />
								<body euler="0 90 0" name="limblink2" pos="0.015 0 0">
									<geom euler="0 0 0" fromto="0 0 0 0.15 0 0" name="geomlimblink2" size="0.03" type="capsule" />
									<joint axis="0 1 0" name="joint_joint6" pos="0 0 0" range="-0.1 0.1" type="hinge" />
								</body>
							</body>
						</body>
					</body>
				</body>
			</body>
		</body>
	</worldbody>
	<actuator>
		<motor ctrllimited="true" ctrlrange="-1 1" joint="joint_joint1" />
		<motor ctrllimited="true" ctrlrange="-1 1" joint="joint_joint19" />
		<motor ctrllimited="true" ctrlrange="-1.2 1.2" joint="joint_joint20" />
		<motor ctrllimited="true" ctrlrange="-1 1" joint="joint_joint21" />
		<motor ctrllimited="true" ctrlrange="-1 1" joint="joint_joint22" />
		<motor ctrllimited="true" ctrlrange="-1 1" joint="joint_joint23" />
		<motor ctrllimited="true" ctrlrange="-1 1" joint="joint_joint24" />
		<motor ctrllimited="true" ctrlrange="-1 1" joint="joint_joint25" />
		<motor ctrllimited="true" ctrlrange="-1 1" joint="joint_joint12" />
		<motor ctrllimited="true" ctrlrange="-1.2 1.2" joint="joint_joint13" />
		<motor ctrllimited="true" ctrlrange="-1 1" joint="joint_joint14" />
		<motor ctrllimited="true" ctrlrange="-1 1" joint="joint_joint15" />
		<motor ctrllimited="true" ctrlrange="-1 1" joint="joint_joint16" />
		<motor ctrllimited="true" ctrlrange="-1 1" joint="joint_joint17" />
		<motor ctrllimited="true" ctrlrange="-1 1" joint="joint_joint18" />
		<motor ctrllimited="true" ctrlrange="-1 1" joint="joint_joint7" />
		<motor ctrllimited="true" ctrlrange="-1.2 1.2" joint="joint_joint8" />
		<motor ctrllimited="true" ctrlrange="-1 1" joint="joint_joint9" />
		<motor ctrllimited="true" ctrlrange="-1 1" joint="joint_joint10" />
		<motor ctrllimited="true" ctrlrange="-1 1" joint="joint_joint11" />
		<motor ctrllimited="true" ctrlrange="-1 1" joint="joint_joint2" />
		<motor ctrllimited="true" ctrlrange="-1.2 1.2" joint="joint_joint3" />
		<motor ctrllimited="true" ctrlrange="-1 1" joint="joint_joint4" />
		<motor ctrllimited="true" ctrlrange="-1 1" joint="joint_joint5" />
		<motor ctrllimited="true" ctrlrange="-1 1" joint="joint_joint6" />
	</actuator>
</mujoco>